<?xml version="1.0"?>
<robot name="cougarbot">
<link name="world"/>
<link name="base_link">
<visual>
<geometry>
<mesh filename="package://cougarbot/meshes/Assembly-
Linear-Motion.stl" scale="0.001 0.001 0.001"/>
</geometry>
<material name="silver">
<color rgba="0.75 0.75 0.75 1"/>
</material>
<origin rpy="1.5708 0 1.5708 " xyz="0 0.04 0"/>
</visual>
<collision>
<geometry>
<cylinder length="0.05" radius="0.1"/>
</geometry>
<origin rpy="0 0 0" xyz="0 0 0.025"/>
</collision>
<inertial>
<mass value="1.0"/>
<origin rpy="0 0 0" xyz="0 0 0.025"/>
<inertia ixx="0.0027" iyy="0.0027" izz="0.005" ixy="0" ixz="0"
iyz="0"/>
</inertial>
</link>
<joint name="fixed" type="fixed">
<parent link="world"/>
<child link="base_link"/>
</joint>
<link name="torso">
<visual>
<geometry>
<mesh
filename="package://cougarbot/meshes/Arm_Base2.stl"
scale="0.001 0.001 0.001"/>
</geometry>
<material name="silver"/>
<origin rpy="0 0 0" xyz="0 0 0.07"/>
</visual>
<collision>
<geometry>
<cylinder length="0.5" radius="0.05"/>
</geometry>
<origin rpy="0 0 0" xyz="0 0 0.25"/>
</collision>
<inertial>
<mass value="1.0"/>
<origin rpy="0 0 0" xyz="0 0 0.25"/>
<inertia ixx="0.02146" iyy="0.02146" izz="0.00125" ixy="0" ixz="0"
iyz="0"/>
</inertial>
</link>
<joint name="hip" type="prismatic">
<axis xyz="1 0 0"/>
<parent link="base_link"/>
<child link="torso"/>
<origin rpy="0 0 0" xyz="0 0 0"/>
<limit lower="-0.25" upper="0.1" effort="100" velocity="0.5"/>
</joint>
<link name="upper_arm">
<visual>
<geometry>
<mesh
filename="package://cougarbot/meshes/Arm_130mm.stl"
scale="0.001 0.001 0.001"/>
</geometry>
<material name="silver"/>
<origin rpy="0 -1.5708 0" xyz="0 0 0.085"/>
</visual>
<collision>
<geometry>
<cylinder length="0.4" radius="0.05"/>
</geometry>
<origin rpy="0 0 0" xyz="0 0 0.2"/>
</collision>
<inertial>
<mass value="1.0"/>
<origin rpy="0 0 0" xyz="0 0 0.2"/>
<inertia ixx="0.01396" iyy="0.01396" izz="0.00125" ixy="0"
ixz="0" iyz="0"/>
</inertial>
</link>
<joint name="shoulder" type="revolute">
<axis xyz="1 0 0"/>
<parent link="torso"/>
<child link="upper_arm"/>
<origin rpy="0 0 0" xyz="0 0 0.17"/>
<limit lower="-1.0" upper="2.0" effort="100" velocity="0.5"/>
</joint>
<link name="lower_arm">
<visual>
<geometry>
<mesh filename="package://cougarbot/meshes/Arm_110mm.stl"
scale="0.001 0.001 0.001"/>
</geometry>
<material name="silver"/>
<origin rpy="0 -1.5708 0" xyz="0 0 0.05"/>
</visual>
<collision>
<geometry>
<cylinder length="0.4" radius="0.05"/>
</geometry>
<origin rpy="0 0 0" xyz="0 0 0.2"/>
</collision>
<inertial>
<mass value="1.0"/>
<origin rpy="0 0 0" xyz="0 0 0"/>
<inertia ixx="0.01396" iyy="0.01396" izz="0.00125" ixy="0"
ixz="0" iyz="0"/>
</inertial>
</link>
<joint name="elbow" type="revolute">
<axis xyz="1 0 0"/>
<parent link="upper_arm"/>
<child link="lower_arm"/>
<origin rpy="0 0 0" xyz="-0.03 0 0.15"/>
<limit lower="-1.5" upper="1.5" effort="100" velocity="1.0"/>
</joint>
<transmission name="tran0">
<type>transmission_interface/SimpleTransmission</type>
<joint name="hip">
<hardwareInterface>PositionJointInterface</hardwareInterface>
</joint>
<actuator name="motor0">
<hardwareInterface>PositionJointInterface</hardwareInterface>
<mechanicalReduction>1</mechanicalReduction>
</actuator>
</transmission>
<transmission name="tran1">
<type>transmission_interface/SimpleTransmission</type>
<joint name="shoulder">
<hardwareInterface>PositionJointInterface</hardwareInterface>
</joint>
<actuator name="motor1">
<hardwareInterface>PositionJointInterface</hardwareInterface>
<mechanicalReduction>1</mechanicalReduction>
</actuator>
</transmission>
<transmission name="tran2">
<type>transmission_interface/SimpleTransmission</type>
<joint name="elbow">
<hardwareInterface>PositionJointInterface</hardwareInterface>
</joint>
<actuator name="motor2">
<hardwareInterface>PositionJointInterface</hardwareInterface>
<mechanicalReduction>1</mechanicalReduction>
</actuator>
</transmission>
<transmission name="tran3">
<type>transmission_interface/SimpleTransmission</type>
<joint name="wrist">
<hardwareInterface>PositionJointInterface</hardwareInterface>
</joint>
<actuator name="motor3">
<hardwareInterface>PositionJointInterface</hardwareInterface>
<mechanicalReduction>1</mechanicalReduction>
</actuator>
</transmission>
<gazebo>
<plugin name="control" filename="libgazebo_ros_control.so"/>
</gazebo>
</robot>

