<?xml version="1.0" ?>
<!-- =================================================================================== -->
<!-- |    This document was autogenerated by xacro from src/prr_description/urdf/prr.urdf.xacro | -->
<!-- |    EDITING THIS FILE BY HAND IS NOT RECOMMENDED                                 | -->
<!-- =================================================================================== -->
<robot name="my_robot">
  <material name="green">
    <color rgba="0 0.6 0 1"/>
  </material>
  <material name="gray">
    <color rgba="0.7 0.7 0.7 1"/>
  </material>
  <link name="world"/>
  <joint name="fixed_base" type="fixed">
    <parent link="world"/>
    <child link="base_link"/>
  </joint>
  <link name="base_link">
    <visual>
      <geometry>
        <box size="0.6 0.4 0.2"/>
      </geometry>
      <origin rpy="0 0 0" xyz="0 0 0.1"/>
      <material name="green"/>
    </visual>
    <collision>
      <geometry>
        <box size="0.6 0.4 0.2"/>
      </geometry>
      <origin rpy="0 0 0" xyz="0 0 0.1"/>
    </collision>
    <inertial>
      <mass value="5.0"/>
      <origin rpy="0 0 0" xyz="0 0 0.1"/>
      <inertia ixx="0.08333333333333336" ixy="0" ixz="0" iyy="0.16666666666666669" iyz="0" izz="0.21666666666666667"/>
    </inertial>
  </link>
  <link name="shoulder_link">
    <visual>
      <geometry>
        <cylinder length="0.3" radius="0.1"/>
      </geometry>
      <origin rpy="0 0 0" xyz="0 0 0"/>
      <material name="gray"/>
    </visual>
    <collision>
      <geometry>
        <cylinder length="0.3" radius="0.1"/>
      </geometry>
      <origin rpy="0 0 0" xyz="0 0 0"/>
    </collision>
    <inertial>
      <mass value="1.0"/>
      <origin rpy="1.5707963267948966 0 0" xyz="0 0 0"/>
      <inertia ixx="0.009999999999999998" ixy="0" ixz="0" iyy="0.009999999999999998" iyz="0" izz="0.005000000000000001"/>
    </inertial>
  </link>
  <joint name="base_shoulder_joint" type="prismatic">
    <parent link="base_link"/>
    <child link="shoulder_link"/>
    <origin rpy="0 0 0" xyz="0 0 0.2"/>
    <axis xyz="0 0 1"/>
    <limit effort="10" lower="-0.05" upper="0.14" velocity="10"/>
  </joint>
  <link name="arm_link">
    <visual>
      <geometry>
        <cylinder length="0.25" radius="0.05"/>
      </geometry>
      <origin rpy="0 0 0" xyz="0 0 0.1"/>
      <material name="gray"/>
    </visual>
    <collision>
      <geometry>
        <cylinder length="0.25" radius="0.05"/>
      </geometry>
      <origin rpy="0 0 0" xyz="0 0 0.1"/>
    </collision>
    <inertial>
      <mass value="1.0"/>
      <origin rpy="1.5707963267948966 0 0" xyz="0 0 0"/>
      <inertia ixx="0.005833333333333334" ixy="0" ixz="0" iyy="0.005833333333333334" iyz="0" izz="0.0012500000000000002"/>
    </inertial>
  </link>
  <joint name="arm_joint" type="revolute">
    <parent link="shoulder_link"/>
    <child link="arm_link"/>
    <origin rpy="0 0 0" xyz="0 0 0.15"/>
    <axis xyz="0 1 0"/>
    <limit effort="10" lower="-2.1" upper="2.1" velocity="10"/>
  </joint>
  <link name="link3">
    <visual>
      <geometry>
        <cylinder length="0.25" radius="0.05"/>
      </geometry>
      <origin rpy="0 0 0" xyz="0 0 0.125"/>
      <material name="gray"/>
    </visual>
    <collision>
      <geometry>
        <cylinder length="0.25" radius="0.05"/>
      </geometry>
      <origin rpy="0 0 0" xyz="0 0 0.125"/>
    </collision>
    <inertial>
      <mass value="1.0"/>
      <origin rpy="1.5707963267948966 0 0" xyz="0 0 0"/>
      <inertia ixx="0.005833333333333334" ixy="0" ixz="0" iyy="0.005833333333333334" iyz="0" izz="0.0012500000000000002"/>
    </inertial>
  </link>
  <joint name="joint3" type="revolute">
    <parent link="arm_link"/>
    <child link="link3"/>
    <origin rpy="0 0 0" xyz="0 0 0.2"/>
    <axis xyz="0 1 0"/>
    <limit effort="10" lower="-2.3" upper="2.3" velocity="10"/>
  </joint>
  <gazebo>
    <plugin filename="gz_ros2_control-system" name="gz_ros2_control::GazeboSimROS2ControlPlugin">
      <parameters>/home/csayar/prr_ws/install/prr_description/share/prr_description/config/my_controllers.yaml</parameters>
    </plugin>
  </gazebo>
  <ros2_control name="GazeboSystem" type="system">
    <hardware>
      <plugin>gz_ros2_control/GazeboSimSystem</plugin>
    </hardware>
    <joint name="base_shoulder_joint">
      <command_interface name="position">
        <param name="min">0</param>
        <param name="max">0.14</param>
      </command_interface>
      <state_interface name="position"/>
      <state_interface name="velocity"/>
    </joint>
    <joint name="arm_joint">
      <command_interface name="position">
        <param name="min">-2.1</param>
        <param name="max">2.1</param>
      </command_interface>
      <state_interface name="position"/>
      <state_interface name="velocity"/>
    </joint>
    <joint name="joint3">
      <command_interface name="position">
        <param name="min">-2.3</param>
        <param name="max">2.3</param>
      </command_interface>
      <state_interface name="position"/>
      <state_interface name="velocity"/>
    </joint>
  </ros2_control>
</robot>
